Workbook

Sheet 总览
A1: 固定翼飞控就业学习计划 2026-08-03 至 2027-08-01｜52周｜每周约12.5小时
A4: 关键设置 | B4: 内容
A5: 主求职方向 | B5: 固定翼飞控/控制算法
A6: 扩展方向 | B6: 机器人运动控制
A7: 工程补充 | B7: 飞控软件/嵌入式
A8: 计划开始 | B8: 46237
A9: 计划结束 | B9: 46600
A10: 每周计划 | B10: 12.5小时（周一至周五各1.5h，周六4h，周日1h）
A12: 今日入口 | B12: 日期 | C12: 周次 | D12: 阶段 | E12: 主题 | F12: 今日任务 | G12: 计划时长 | H12: 状态
A13: =IFERROR(INDEX(每日计划!$D$4:$D$367,MATCH(TODAY(),每日计划!$A$4:$A$367,0)),"非计划日") -> 周二 | B13: =TODAY() -> 46238 | C13: =IFERROR(INDEX(每日计划!$B$4:$B$367,MATCH(TODAY(),每日计划!$A$4:$A$367,0)),"") -> 1 | D13: =IFERROR(INDEX(每日计划!$C$4:$C$367,MATCH(TODAY(),每日计划!$A$4:$A$367,0)),"") -> 基础与工具 | E13: =IFERROR(INDEX(每日计划!$E$4:$E$367,MATCH(TODAY(),每日计划!$A$4:$A$367,0)),"") -> 方向确认与环境搭建 | F13: =IFERROR(INDEX(每日计划!$F$4:$F$367,MATCH(TODAY(),每日计划!$A$4:$A$367,0)),"今天不在计划周期内") -> 仿真/数据：用Python读取一份CSV并绘制折线图 | G13: =IFERROR(INDEX(每日计划!$H$4:$H$367,MATCH(TODAY(),每日计划!$A$4:$A$367,0)),"") -> 1.5 | H13: =IFERROR(INDEX(每日计划!$J$4:$J$367,MATCH(TODAY(),每日计划!$A$4:$A$367,0)),"") -> 进行中
A16: 总体进度 | B16: 计划任务 | C16: 已完成 | D16: 完成率 | E16: 计划时长 | F16: 实际时长 | G16: 时间达成率 | H16: 当前连续性
A17: ="截至 "&TEXT(TODAY(),"yyyy-mm-dd") -> 截至 2026-08-04 | B17: =COUNTA(每日计划!$A$4:$A$367) -> 364 | C17: =COUNTIF(每日计划!$J$4:$J$367,"已完成") -> 1 | D17: =C17/B17 -> 0.0027472527 | E17: =SUM(每日计划!$H$4:$H$367) -> 650 | F17: =SUM(每日计划!$I$4:$I$367) -> 0 | G17: =IFERROR(F17/E17,0) -> 0 | H17: =COUNTIFS(每日计划!$A$4:$A$367,"<="&TODAY(),每日计划!$J$4:$J$367,"已完成")&" 个历史完成日" -> 1 个历史完成日
A20: 阶段 | B20: 周数 | C20: 计划时长 | D20: 已完成任务
A21: 基础与工具 | B21: =COUNTIF(周复盘!$D$4:$D$55,A21) -> 13 | C21: =SUMIF(每日计划!$C$4:$C$367,A21,每日计划!$H$4:$H$367) -> 162.5 | D21: =COUNTIFS(每日计划!$C$4:$C$367,A21,每日计划!$J$4:$J$367,"已完成") -> 1
A22: PX4与基线控制 | B22: =COUNTIF(周复盘!$D$4:$D$55,A22) -> 13 | C22: =SUMIF(每日计划!$C$4:$C$367,A22,每日计划!$H$4:$H$367) -> 162.5 | D22: =COUNTIFS(每日计划!$C$4:$C$367,A22,每日计划!$J$4:$J$367,"已完成") -> 0
A23: 算法部署与验证 | B23: =COUNTIF(周复盘!$D$4:$D$55,A23) -> 13 | C23: =SUMIF(每日计划!$C$4:$C$367,A23,每日计划!$H$4:$H$367) -> 162.5 | D23: =COUNTIFS(每日计划!$C$4:$C$367,A23,每日计划!$J$4:$J$367,"已完成") -> 0
A24: 工程验证与求职 | B24: =COUNTIF(周复盘!$D$4:$D$55,A24) -> 13 | C24: =SUMIF(每日计划!$C$4:$C$367,A24,每日计划!$H$4:$H$367) -> 162.5 | D24: =COUNTIFS(每日计划!$C$4:$C$367,A24,每日计划!$J$4:$J$367,"已完成") -> 0
A26: 执行规则
A27: 1 | B27: 每天先打开“总览”看今日任务；完成后只填写“实际时长、状态、困难/复盘、成果链接”。
A28: 2 | B28: 任务超过计划时长仍未完成时，记录阻塞点并停止扩张范围；周日统一调整，不用熬夜补齐。
A29: 3 | B29: 考试、项目出差或试飞冲突时，可将状态设为“跳过/调整”，但必须在周复盘填写替代安排。

Sheet 每日计划
A1: 每日计划与打卡 只编辑浅黄色列：实际时长、状态、困难/复盘、成果链接
A3: 日期 | B3: 周次 | C3: 阶段 | D3: 星期 | E3: 本周主题 | F3: 当日任务 | G3: 预期产出 | H3: 计划时长(h) | I3: 实际时长(h) | J3: 状态 | K3: 困难/复盘 | L3: 成果链接/提交
A4: 46237 | B4: 1 | C4: 基础与工具 | D4: 周一 | E4: 方向确认与环境搭建 | F4: 理论：列出飞控算法、飞控软件、机器人控制三类岗位各10个JD关键词 | G4: 结构化笔记/公式页 | H4: 1.5 | J4: 已完成 | K4: 了解关键词含义，总结各岗位需求 | L4: 文件夹中"关键词.md"
A5: 46238 | B5: 1 | C5: 基础与工具 | D5: 周二 | E5: 方向确认与环境搭建 | F5: 仿真/数据：用Python读取一份CSV并绘制折线图 | G5: 可运行脚本与结果图 | H5: 1.5 | J5: 进行中
A6: 46239 | B6: 1 | C6: 基础与工具 | D6: 周三 | E6: 方向确认与环境搭建 | F6: 编程：编译运行首个C++程序，熟悉编译器与终端 | G6: 可编译代码与提交记录 | H6: 1.5 | J6: 未开始
A7: 46240 | B7: 1 | C7: 基础与工具 | D7: 周四 | E7: 方向确认与环境搭建 | F7: 平台实践：安装PX4依赖并浏览官方固定翼文档结构 | G7: 截图/日志/源码阅读记录 | H7: 1.5 | J7: 未开始
A8: 46241 | B8: 1 | C8: 基础与工具 | D8: 周五 | E8: 方向确认与环境搭建 | F8: 验证：检查全部工具版本，记录安装问题和解决过程 | G8: 指标表、失败原因与修正 | H8: 1.5 | J8: 未开始
A9: 46242 | B9: 1 | C9: 基础与工具 | D9: 周六 | E9: 方向确认与环境搭建 | F9: 周成果：形成《现状盘点与一年目标》1页文档 | H9: 4 | J9: 未开始
A10: 46243 | B10: 1 | C10: 基础与工具 | D10: 周日 | E10: 方向确认与环境搭建 | F10: 周复盘：检查“方向确认与环境搭建”完成情况，整理笔记与代码，填写周复盘并为下周预留调整空间 | G10: 周复盘记录、完成率和下周调整项 | H10: 1 | J10: 未开始
A11: 46244 | B11: 2 | C11: 基础与工具 | D11: 周一 | E11: Linux命令行与Git | F11: 理论：练习文件、权限、进程、管道、环境变量与SSH基础 | G11: 结构化笔记/公式页 | H11: 1.5 | J11: 未开始
A12: 46245 | B12: 2 | C12: 基础与工具 | D12: 周二 | E12: Linux命令行与Git | F12: 仿真/数据：用Git完成分支、提交、合并和冲突解决练习 | G12: 可运行脚本与结果图 | H12: 1.5 | J12: 未开始
A13: 46246 | B13: 2 | C13: 基础与工具 | D13: 周三 | E13: Linux命令行与Git | F13: 编程：写一个C++日志解析小程序并用Git管理 | G13: 可编译代码与提交记录 | H13: 1.5 | J13: 未开始
A14: 46247 | B14: 2 | C14: 基础与工具 | D14: 周四 | E14: Linux命令行与Git | F14: 平台实践：克隆PX4仓库，阅读目录结构和贡献规范 | G14: 截图/日志/源码阅读记录 | H14: 1.5 | J14: 未开始
A15: 46248 | B15: 2 | C15: 基础与工具 | D15: 周五 | E15: Linux命令行与Git | F15: 验证：故意制造一次合并冲突并完整解决 | G15: 指标表、失败原因与修正 | H15: 1.5 | J15: 未开始
A16: 46249 | B16: 2 | C16: 基础与工具 | D16: 周六 | E16: Linux命令行与Git | F16: 周成果：建立个人学习仓库，提交规范README | H16: 4 | J16: 未开始
A17: 46250 | B17: 2 | C17: 基础与工具 | D17: 周日 | E17: Linux命令行与Git | F17: 周复盘：检查“Linux命令行与Git”完成情况，整理笔记与代码，填写周复盘并为下周预留调整空间 | G17: 周复盘记录、完成率和下周调整项 | H17: 1 | J17: 未开始
A18: 46251 | B18: 3 | C18: 基础与工具 | D18: 周一 | E18: C++语法与数据结构 | F18: 理论：复习类型、函数、引用、const、类和STL容器 | G18: 结构化笔记/公式页 | H18: 1.5 | J18: 未开始
A19: 46252 | B19: 3 | C19: 基础与工具 | D19: 周二 | E19: C++语法与数据结构 | F19: 仿真/数据：实现向量/矩阵基础运算并编写输入输出 | G19: 可运行脚本与结果图 | H19: 1.5 | J19: 未开始
A20: 46253 | B20: 3 | C20: 基础与工具 | D20: 周三 | E20: C++语法与数据结构 | F20: 编程：练习vector、map、algorithm和lambda | G20: 可编译代码与提交记录 | H20: 1.5 | J20: 未开始
A21: 46254 | B21: 3 | C21: 基础与工具 | D21: 周四 | E21: C++语法与数据结构 | F21: 平台实践：定位PX4源码中的常用容器与数学类型 | G21: 截图/日志/源码阅读记录 | H21: 1.5 | J21: 未开始
A22: 46255 | B22: 3 | C22: 基础与工具 | D22: 周五 | E22: C++语法与数据结构 | F22: 验证：用10组边界数据测试数值程序 | G22: 指标表、失败原因与修正 | H22: 1.5 | J22: 未开始
A23: 46256 | B23: 3 | C23: 基础与工具 | D23: 周六 | E23: C++语法与数据结构 | F23: 周成果：完成一个带说明的C++数值计算小项目 | H23: 4 | J23: 未开始
A24: 46257 | B24: 3 | C24: 基础与工具 | D24: 周日 | E24: C++语法与数据结构 | F24: 周复盘：检查“C++语法与数据结构”完成情况，整理笔记与代码，填写周复盘并为下周预留调整空间 | G24: 周复盘记录、完成率和下周调整项 | H24: 1 | J24: 未开始
A25: 46258 | B25: 4 | C25: 基础与工具 | D25: 周一 | E25: 现代C++与资源管理 | F25: 理论：梳理栈/堆、生命周期、拷贝与移动语义 | G25: 结构化笔记/公式页 | H25: 1.5 | J25: 未开始
A26: 46259 | B26: 4 | C26: 基础与工具 | D26: 周二 | E26: 现代C++与资源管理 | F26: 仿真/数据：重构上周程序，消除裸指针和重复资源释放 | G26: 可运行脚本与结果图 | H26: 1.5 | J26: 未开始
A27: 46260 | B27: 4 | C27: 基础与工具 | D27: 周三 | E27: 现代C++与资源管理 | F27: 编程：练习unique_ptr、shared_ptr、optional和enum class | G27: 可编译代码与提交记录 | H27: 1.5 | J27: 未开始
A28: 46261 | B28: 4 | C28: 基础与工具 | D28: 周四 | E28: 现代C++与资源管理 | F28: 平台实践：阅读PX4模块类的初始化和生命周期管理 | G28: 截图/日志/源码阅读记录 | H28: 1.5 | J28: 未开始
A29: 46262 | B29: 4 | C29: 基础与工具 | D29: 周五 | E29: 现代C++与资源管理 | F29: 验证：用编译警告或检查工具排查资源问题 | G29: 指标表、失败原因与修正 | H29: 1.5 | J29: 未开始
A30: 46263 | B30: 4 | C30: 基础与工具 | D30: 周六 | E30: 现代C++与资源管理 | F30: 周成果：输出《现代C++常见错误清单》 | H30: 4 | J30: 未开始
A31: 46264 | B31: 4 | C31: 基础与工具 | D31: 周日 | E31: 现代C++与资源管理 | F31: 周复盘：检查“现代C++与资源管理”完成情况，整理笔记与代码，填写周复盘并为下周预留调整空间 | G31: 周复盘记录、完成率和下周调整项 | H31: 1 | J31: 未开始
A32: 46265 | B32: 5 | C32: 基础与工具 | D32: 周一 | E32: CMake、调试与测试 | F32: 理论：理解编译、链接、静态库、动态库与CMake target | G32: 结构化笔记/公式页 | H32: 1.5 | J32: 未开始
A33: 46266 | B33: 5 | C33: 基础与工具 | D33: 周二 | E33: CMake、调试与测试 | F33: 仿真/数据：拆分多文件项目并添加CMakeLists.txt | G33: 可运行脚本与结果图 | H33: 1.5 | J33: 未开始
A34: 46267 | B34: 5 | C34: 基础与工具 | D34: 周三 | E34: CMake、调试与测试 | F34: 编程：使用断点、调用栈和变量监视定位一个缺陷 | G34: 可编译代码与提交记录 | H34: 1.5 | J34: 未开始
A35: 46268 | B35: 5 | C35: 基础与工具 | D35: 周四 | E35: CMake、调试与测试 | F35: 平台实践：查看PX4构建命令及模块构建配置 | G35: 截图/日志/源码阅读记录 | H35: 1.5 | J35: 未开始
A36: 46269 | B36: 5 | C36: 基础与工具 | D36: 周五 | E36: CMake、调试与测试 | F36: 验证：为数值模块增加至少5个单元测试 | G36: 指标表、失败原因与修正 | H36: 1.5 | J36: 未开始
A37: 46270 | B37: 5 | C37: 基础与工具 | D37: 周六 | E37: CMake、调试与测试 | F37: 周成果：形成可一键构建和测试的工程模板 | H37: 4 | J37: 未开始
A38: 46271 | B38: 5 | C38: 基础与工具 | D38: 周日 | E38: CMake、调试与测试 | F38: 周复盘：检查“CMake、调试与测试”完成情况，整理笔记与代码，填写周复盘并为下周预留调整空间 | G38: 周复盘记录、完成率和下周调整项 | H38: 1 | J38: 未开始
A39: 46272 | B39: 6 | C39: 基础与工具 | D39: 周一 | E39: 坐标系与姿态表示 | F39: 理论：复习地理/机体/风轴系、欧拉角、旋转矩阵与四元数 | G39: 结构化笔记/公式页 | H39: 1.5 | J39: 未开始
A40: 46273 | B40: 6 | C40: 基础与工具 | D40: 周二 | E40: 坐标系与姿态表示 | F40: 仿真/数据：用MATLAB验证旋转矩阵正交性和姿态变换 | G40: 可运行脚本与结果图 | H40: 1.5 | J40: 未开始
A41: 46274 | B41: 6 | C41: 基础与工具 | D41: 周三 | E41: 坐标系与姿态表示 | F41: 编程：用C++实现欧拉角与四元数转换并测试奇异情况 | G41: 可编译代码与提交记录 | H41: 1.5 | J41: 未开始
...

Sheet 周复盘
A1: 52周复盘 周日填写自评分、主要问题和下周调整；统计列由公式自动计算
A3: 周次 | B3: 开始日期 | C3: 结束日期 | D3: 阶段 | E3: 本周主题 | F3: 周目标 | G3: 计划时长 | H3: 实际时长 | I3: 完成任务 | J3: 总任务 | K3: 完成率 | L3: 自评(1-5) | M3: 问题与下周调整
A4: 1 | B4: 46237 | C4: 46243 | D4: 基础与工具 | E4: 方向确认与环境搭建 | F4: 完成能力自评，搭建Ubuntu/WSL、VS Code、Git、MATLAB/Python环境 | G4: =SUMIF(每日计划!$B$4:$B$367,A4,每日计划!$H$4:$H$367) -> 12.5 | H4: =SUMIF(每日计划!$B$4:$B$367,A4,每日计划!$I$4:$I$367) -> 0 | I4: =COUNTIFS(每日计划!$B$4:$B$367,A4,每日计划!$J$4:$J$367,"已完成") -> 1 | J4: =7 -> 7 | K4: =IFERROR(I4/J4,0) -> 0.14285714
A5: 2 | B5: 46244 | C5: 46250 | D5: 基础与工具 | E5: Linux命令行与Git | F5: 掌握日常开发命令和可追溯的版本管理流程 | G5: =SUMIF(每日计划!$B$4:$B$367,A5,每日计划!$H$4:$H$367) -> 12.5 | H5: =SUMIF(每日计划!$B$4:$B$367,A5,每日计划!$I$4:$I$367) -> 0 | I5: =COUNTIFS(每日计划!$B$4:$B$367,A5,每日计划!$J$4:$J$367,"已完成") -> 0 | J5: =7 -> 7 | K5: =IFERROR(I5/J5,0) -> 0
A6: 3 | B6: 46251 | C6: 46257 | D6: 基础与工具 | E6: C++语法与数据结构 | F6: 能够用C++完成小型数值计算程序 | G6: =SUMIF(每日计划!$B$4:$B$367,A6,每日计划!$H$4:$H$367) -> 12.5 | H6: =SUMIF(每日计划!$B$4:$B$367,A6,每日计划!$I$4:$I$367) -> 0 | I6: =COUNTIFS(每日计划!$B$4:$B$367,A6,每日计划!$J$4:$J$367,"已完成") -> 0 | J6: =7 -> 7 | K6: =IFERROR(I6/J6,0) -> 0
A7: 4 | B7: 46258 | C7: 46264 | D7: 基础与工具 | E7: 现代C++与资源管理 | F7: 理解RAII、智能指针、移动语义和接口设计 | G7: =SUMIF(每日计划!$B$4:$B$367,A7,每日计划!$H$4:$H$367) -> 12.5 | H7: =SUMIF(每日计划!$B$4:$B$367,A7,每日计划!$I$4:$I$367) -> 0 | I7: =COUNTIFS(每日计划!$B$4:$B$367,A7,每日计划!$J$4:$J$367,"已完成") -> 0 | J7: =7 -> 7 | K7: =IFERROR(I7/J7,0) -> 0
A8: 5 | B8: 46265 | C8: 46271 | D8: 基础与工具 | E8: CMake、调试与测试 | F8: 能够构建、调试并测试多文件C++项目 | G8: =SUMIF(每日计划!$B$4:$B$367,A8,每日计划!$H$4:$H$367) -> 12.5 | H8: =SUMIF(每日计划!$B$4:$B$367,A8,每日计划!$I$4:$I$367) -> 0 | I8: =COUNTIFS(每日计划!$B$4:$B$367,A8,每日计划!$J$4:$J$367,"已完成") -> 0 | J8: =7 -> 7 | K8: =IFERROR(I8/J8,0) -> 0
A9: 6 | B9: 46272 | C9: 46278 | D9: 基础与工具 | E9: 坐标系与姿态表示 | F9: 掌握固定翼建模所需坐标变换和姿态数学 | G9: =SUMIF(每日计划!$B$4:$B$367,A9,每日计划!$H$4:$H$367) -> 12.5 | H9: =SUMIF(每日计划!$B$4:$B$367,A9,每日计划!$I$4:$I$367) -> 0 | I9: =COUNTIFS(每日计划!$B$4:$B$367,A9,每日计划!$J$4:$J$367,"已完成") -> 0 | J9: =7 -> 7 | K9: =IFERROR(I9/J9,0) -> 0
A10: 7 | B10: 46279 | C10: 46285 | D10: 基础与工具 | E10: 固定翼六自由度动力学 | F10: 独立写出并仿真刚体六自由度方程 | G10: =SUMIF(每日计划!$B$4:$B$367,A10,每日计划!$H$4:$H$367) -> 12.5 | H10: =SUMIF(每日计划!$B$4:$B$367,A10,每日计划!$I$4:$I$367) -> 0 | I10: =COUNTIFS(每日计划!$B$4:$B$367,A10,每日计划!$J$4:$J$367,"已完成") -> 0 | J10: =7 -> 7 | K10: =IFERROR(I10/J10,0) -> 0
A11: 8 | B11: 46286 | C11: 46292 | D11: 基础与工具 | E11: 气动力、气动力矩与推进 | F11: 理解固定翼力矩来源和主要气动参数 | G11: =SUMIF(每日计划!$B$4:$B$367,A11,每日计划!$H$4:$H$367) -> 12.5 | H11: =SUMIF(每日计划!$B$4:$B$367,A11,每日计划!$I$4:$I$367) -> 0 | I11: =COUNTIFS(每日计划!$B$4:$B$367,A11,每日计划!$J$4:$J$367,"已完成") -> 0 | J11: =7 -> 7 | K11: =IFERROR(I11/J11,0) -> 0
A12: 9 | B12: 46293 | C12: 46299 | D12: 基础与工具 | E12: 配平与线性化 | F12: 完成一个巡航工作点的配平和小扰动模型 | G12: =SUMIF(每日计划!$B$4:$B$367,A12,每日计划!$H$4:$H$367) -> 12.5 | H12: =SUMIF(每日计划!$B$4:$B$367,A12,每日计划!$I$4:$I$367) -> 0 | I12: =COUNTIFS(每日计划!$B$4:$B$367,A12,每日计划!$J$4:$J$367,"已完成") -> 0 | J12: =7 -> 7 | K12: =IFERROR(I12/J12,0) -> 0
A13: 10 | B13: 46300 | C13: 46306 | D13: 基础与工具 | E13: 状态空间、稳定性与模态 | F13: 能解释固定翼纵向和横侧向主要模态 | G13: =SUMIF(每日计划!$B$4:$B$367,A13,每日计划!$H$4:$H$367) -> 12.5 | H13: =SUMIF(每日计划!$B$4:$B$367,A13,每日计划!$I$4:$I$367) -> 0 | I13: =COUNTIFS(每日计划!$B$4:$B$367,A13,每日计划!$J$4:$J$367,"已完成") -> 0 | J13: =7 -> 7 | K13: =IFERROR(I13/J13,0) -> 0
A14: 11 | B14: 46307 | C14: 46313 | D14: 基础与工具 | E14: PID串级控制与抗饱和 | F14: 实现并调通姿态/角速度串级控制基线 | G14: =SUMIF(每日计划!$B$4:$B$367,A14,每日计划!$H$4:$H$367) -> 12.5 | H14: =SUMIF(每日计划!$B$4:$B$367,A14,每日计划!$I$4:$I$367) -> 0 | I14: =COUNTIFS(每日计划!$B$4:$B$367,A14,每日计划!$J$4:$J$367,"已完成") -> 0 | J14: =7 -> 7 | K14: =IFERROR(I14/J14,0) -> 0
A15: 12 | B15: 46314 | C15: 46320 | D15: 基础与工具 | E15: LQR与状态观测 | F15: 实现LQR并理解控制与估计的接口 | G15: =SUMIF(每日计划!$B$4:$B$367,A15,每日计划!$H$4:$H$367) -> 12.5 | H15: =SUMIF(每日计划!$B$4:$B$367,A15,每日计划!$I$4:$I$367) -> 0 | I15: =COUNTIFS(每日计划!$B$4:$B$367,A15,每日计划!$J$4:$J$367,"已完成") -> 0 | J15: =7 -> 7 | K15: =IFERROR(I15/J15,0) -> 0
... A55: 52 | B55: 46594 | C55: 46600 | D55: 工程验证与求职 | E55: 全年验收与下一阶段 | F55: 完成成果归档并制定秋招前滚动计划 | G55: =SUMIF(每日计划!$B$4:$B$367,A55,每日计划!$H$4:$H$367) -> 12.5 | H55: =SUMIF(每日计划!$B$4:$B$367,A55,每日计划!$I$4:$I$367) -> 0 | I55: =COUNTIFS(每日计划!$B$4:$B$367,A55,每日计划!$J$4:$J$367,"已完成") -> 0 | J55: =7 -> 7 | K55: =IFERROR(I55/J55,0) -> 0

Sheet 能力地图
A1: 能力地图 每月最后一个周日更新当前等级；所有等级都要用作品、代码、报告或实飞数据证明
A3: 能力模块 | B3: 当前自评(1-5) | C3: 一年目标 | D3: 达标证据 | E3: 第1阶段 | F3: 第2阶段 | G3: 第3阶段 | H3: 第4阶段
A4: C++工程能力 | B4: 1 | C4: 4 | D4: 能阅读/修改PX4模块；有CMake、测试、调试记录 | E4: 语法/STL/RAII | F4: PX4模块与日志工具 | G4: 实时控制器接口 | H4: 测试、优化与文档
A5: Linux/Git/CMake | B5: 1 | C5: 4 | D5: 干净环境一键构建；提交历史清晰；能定位构建问题 | E5: 工具链熟练 | F5: PX4构建 | G5: 自动化试验 | H5: 可复现作品集
A6: 固定翼动力学 | B6: 2 | C6: 4 | D6: 六自由度模型、配平线性化、模态分析报告 | E6: 完整建模 | F6: 联系PX4控制链 | G6: 解释摄动结果 | H6: 面试口头推导
A7: 控制理论与设计 | B7: 2 | C7: 4 | D7: PID/LQR/约束控制对比和稳定性说明 | E7: 基线控制器 | F7: 工程基线 | G7: 新算法部署 | H7: 面试与技术报告
A8: PX4固定翼 | B8: 1 | C8: 4 | D8: SITL→源码→模块修改→日志→HIL/实飞闭环 | E8: 跑通SITL | F8: 读懂控制栈 | G8: 集成新控制器 | H8: HIL/实飞与作品集
A9: MATLAB/Python分析 | B9: 2 | C9: 4 | D9: 批量仿真、ULog分析、Monte Carlo自动报告 | E9: 建模与绘图 | F9: 日志分析工具 | G9: 自动化回归 | H9: 成果汇总
A10: 状态估计/系统辨识 | B10: 1 | C10: 3 | D10: 能解释EKF接口；完成一次数据辨识与验证 | E10: 观测器基础 | F10: 辨识实践 | G10: 噪声/延迟分析 | H10: 面试复习
A11: HIL/实飞与安全 | B11: 1 | C11: 3 | D11: 检查表、试飞卡、日志及SIL/HIL/实飞对比 | E11: 安全意识 | F11: 失效仿真 | G11: 回退机制 | H11: HIL/实飞验证
A12: 技术表达与求职 | B12: 1 | C12: 4 | D12: 两版简历、10页简报、3分钟视频、面试题库 | E12: 方向与记录 | F12: 阶段报告 | G12: 项目结论 | H12: 完整投递材料
A15: 等级说明
A16: 1 入门 | B16: 知道概念，需跟随教程 | C16: 2 基础 | D16: 能独立完成小练习 | E16: 3 可用 | F16: 能完成项目子任务 | G16: 4 求职 | H16: 能独立交付并接受深挖
A17: 5 深入 | B17: 能设计方案、解释权衡并指导他人
A18: 更新原则 | B18: 没有代码、报告、日志或实验数据支撑时，不提高自评分。
